Workbook

Sheet Sheet1
C1: WT 24 hours | K1: Set 1 24h | S1: Set 2 24h | AB1: Set 4 24h | AK1: Set5 24 hours | AT1: GFP 24h
C2: Target | D2: Cq | E2: Avg Cq | F2: ∆Cq | G2: Avg ∆Cq | H2: ∆∆Cq | I2: 2-∆∆Cq | K2: Sample | L2: Target | M2: Cq | N2: Avg Cq | O2: ∆Cq | P2: ∆∆Cq | Q2: 2-∆∆Cq | S2: Well Position | T2: Sample | U2: Target | V2: Cq | W2: Avg Cq | X2: ∆Cq | Y2: ∆∆Cq | Z2: 2-∆∆Cq | AB2: Well Position | AC2: Sample | AD2: Target | AE2: Cq | AF2: Avg Cq | AG2: ∆Cq | AH2: ∆∆Cq | AI2: 2-∆∆Cq | AK2: Well Position | AL2: Sample | AM2: Target | AN2: Cq | AO2: Avg Cq | AP2: ∆Cq | AQ2: ∆∆Cq | AR2: 2-∆∆Cq | AT2: Well Position | AU2: Sample | AV2: Target | AW2: Cq | AX2: Avg Cq | AY2: ∆Cq | AZ2: ∆∆Cq | BA2: 2-∆∆Cq
A3: Housekeeping Gene | B3: =C3 -> GAPDH | C3: GAPDH | D3: 20.427816 | E3: =AVERAGE(D3:D5) -> 20.471573 | F3: N/A | K3: Set 1 24h | L3: GAPDH | M3: 19.593802 | N3: 19.521473 | T3: Set 2 24h | U3: GAPDH | V3: 17.46995 | W3: 17.5296 | AC3: Set 4 24h | AD3: GAPDH | AE3: 20.722142 | AF3: 20.368307 | AL3: Set 5 24h | AM3: GAPDH | AN3: 20.722142 | AO3: 20.368307 | AU3: GFP 24h | AV3: GAPDH | AX3: 17.892146
C4: GAPDH | K4: Set 1 24h | L4: GAPDH | M4: 19.382193 | T4: Set 2 24h | U4: GAPDH | V4: 17.578786 | AC4: Set 4 24h | AD4: GAPDH | AE4: 19.967785 | AL4: Set 5 24h | AM4: GAPDH | AN4: 19.967785 | AU4: GFP 24h | AV4: GAPDH | AW4: 17.845502
C5: GAPDH | D5: 20.51533 | K5: Set 1 24h | L5: GAPDH | M5: 19.588425 | T5: Set 2 24h | U5: GAPDH | V5: 17.540063 | AC5: Set 4 24h | AD5: GAPDH | AE5: 20.414992 | AL5: Set 5 24h | AM5: GAPDH | AN5: 20.414992 | AU5: GFP 24h | AV5: GAPDH | AW5: 17.93879
C6: GAPDH | E6: =AVERAGE(D6:D8) -> 20.663111 | K6: Set 1 24h | L6: GAPDH | M6: 17.611369 | N6: 17.648709 | T6: Set 2 24h | U6: GAPDH | V6: 17.707659 | W6: 17.858728 | AC6: Set 4 24h | AD6: GAPDH | AE6: 20.630732 | AF6: 20.320845 | AL6: Set 5 24h | AM6: GAPDH | AN6: 20.630732 | AO6: 20.320845 | AU6: GFP 24h | AV6: GAPDH | AW6: 18.315127 | AX6: 18.462492
C7: GAPDH | D7: 20.71529 | K7: Set 1 24h | L7: GAPDH | M7: 17.628815 | T7: Set 2 24h | U7: GAPDH | V7: 17.8579 | AC7: Set 4 24h | AD7: GAPDH | AE7: 20.256084 | AL7: Set 5 24h | AM7: GAPDH | AN7: 20.256084 | AU7: GFP 24h | AV7: GAPDH | AW7: 18.536358
C8: GAPDH | D8: 20.610931 | K8: Set 1 24h | L8: GAPDH | M8: 17.705944 | T8: Set 2 24h | U8: GAPDH | V8: 18.010625 | AC8: Set 4 24h | AD8: GAPDH | AE8: 20.075719 | AL8: Set 5 24h | AM8: GAPDH | AN8: 20.075719 | AU8: GFP 24h | AV8: GAPDH | AW8: 18.535992
C9: GAPDH | D9: 20.672207 | E9: =AVERAGE(D9:D11) -> 20.606235 | K9: Set 1 24h | L9: GAPDH | M9: 19.22486 | N9: 19.241817 | T9: Set 2 24h | U9: GAPDH | V9: 19.328557 | W9: 19.263755 | AC9: Set 4 24h | AD9: GAPDH | AE9: 19.142668 | AF9: 19.237758 | AL9: Set 5 24h | AM9: GAPDH | AN9: 19.142668 | AO9: 19.237758 | AU9: GFP 24h | AV9: GAPDH | AW9: 18.483091 | AX9: 18.570622
C10: GAPDH | K10: Set 1 24h | L10: GAPDH | M10: 19.644558 | T10: Set 2 24h | U10: GAPDH | V10: 19.610464 | AC10: Set 4 24h | AD10: GAPDH | AE10: 19.318447 | AL10: Set 5 24h | AM10: GAPDH | AN10: 19.318447 | AU10: GFP 24h | AV10: GAPDH | AW10: 18.980717
C11: GAPDH | D11: 20.540263 | K11: Set 1 24h | L11: GAPDH | M11: 18.856033 | T11: Set 2 24h | U11: GAPDH | V11: 18.852243 | AC11: Set 4 24h | AD11: GAPDH | AE11: 19.252159 | AL11: Set 5 24h | AM11: GAPDH | AN11: 19.252159 | AU11: GFP 24h | AV11: GAPDH | AW11: 18.248058
A12: Gene 1 | B12: =C12 -> nsP3 | C12: nsP3 | E12: =AVERAGE(D12:D14) -> 18.462688 | F12: =E12-E3 -> -2.0088851 | G12: =AVERAGE(F12:F20) -> -1.918063 | H12: =F12-G12 -> -0.090822117 | I12: =2^-(H12) -> 1.0649769 | K12: Set 1 24h | L12: nsP3 | M12: 19.075895 | N12: 18.867162 | O12: -0.65431147 | P12: 1.2637515 | Q12: 0.41645961 | T12: Set 2 24h | U12: nsP3 | V12: 18.231773 | W12: 18.070737 | X12: 0.54113764 | Y12: 2.4592006 | Z12: 0.1818473 | AC12: Set 4 24h | AD12: nsP3 | AE12: 20.782261 | AF12: 20.708842 | AG12: 0.3405353 | AH12: 2.2585983 | AI12: 0.20897492 | AL12: Set 5 24h | AM12: nsP3 | AO12: 18.88954 | AP12: -1.4787667 | AQ12: 0.43929626 | AR12: 0.73749427 | AU12: GFP 24h | AV12: nsP3 | AW12: 17.757053 | AX12: 17.463924 | AY12: -0.42822189 | AZ12: 1.4898411 | BA12: 0.35605176
C13: nsP3 | K13: Set 1 24h | L13: nsP3 | M13: 18.406874 | T13: Set 2 24h | U13: nsP3 | V13: 17.814543 | AC13: Set 4 24h | AD13: nsP3 | AE13: 20.611873 | AL13: Set 5 24h | AM13: nsP3 | AU13: GFP 24h | AV13: nsP3 | AW13: 17.049854
C14: nsP3 | D14: 18.462688 | K14: Set 1 24h | L14: nsP3 | M14: 19.118717 | T14: Set 2 24h | U14: nsP3 | V14: 18.165897 | AC14: Set 4 24h | AD14: nsP3 | AE14: 20.732391 | AL14: Set 5 24h | AM14: nsP3 | AN14: 18.88954 | AU14: GFP 24h | AV14: nsP3 | AW14: 17.584865
C15: nsP3 | D15: 19.064071 | E15: =AVERAGE(D15:D17) -> 18.70445 | F15: =E15-E6 -> -1.9586608 | H15: =F15-G12 -> -0.04059784 | I15: =2^-(H15) -> 1.02854 | K15: Set 1 24h | L15: nsP3 | M15: 18.110747 | N15: 17.858329 | O15: 0.20961933 | P15: 2.1276823 | Q15: 0.22882517 | T15: Set 2 24h | U15: nsP3 | V15: 18.207993 | W15: 17.751046 | X15: -0.10768172 | Y15: 1.8103813 | Z15: 0.28511557 | AC15: Set 4 24h | AD15: nsP3 | AE15: 20.940366 | AF15: 20.798444 | AG15: 0.47759874 | AH15: 2.3956617 | AI15: 0.19003516 | AL15: Set 5 24h | AM15: nsP3 | AO15: 19.140345 | AP15: -1.1805004 | AQ15: 0.73756263 | AR15: 0.59975175 | AU15: GFP 24h | AV15: nsP3 | AW15: 17.027959 | AX15: 17.037905 | AY15: -1.4245872 | AZ15: 0.49347578 | BA15: 0.71031173
C16: nsP3 | D16: 18.513969 | K16: Set 1 24h | L16: nsP3 | M16: 18.264739 | T16: Set 2 24h | U16: nsP3 | V16: 17.825047 | AC16: Set 4 24h | AD16: nsP3 | AE16: 20.643332 | AL16: Set 5 24h | AM16: nsP3 | AU16: GFP 24h | AV16: nsP3 | AW16: 17.047851
C17: nsP3 | D17: 18.53531 | K17: Set 1 24h | L17: nsP3 | M17: 17.1995 | T17: Set 2 24h | U17: nsP3 | V17: 17.220099 | AC17: Set 4 24h | AD17: nsP3 | AE17: 20.811632 | AL17: Set 5 24h | AM17: nsP3 | AN17: 19.140345 | AU17: GFP 24h | AV17: nsP3
C18: nsP3 | E18: =AVERAGE(D18:D20) -> 18.819592 | F18: =E18-E9 -> -1.786643 | H18: =F18-G12 -> 0.13141996 | I18: =2^-(H18) -> 0.91293246 | K18: Set 1 24h | L18: nsP3 | M18: 18.900067 | N18: 19.467777 | O18: 0.22595981 | P18: 2.1440228 | Q18: 0.22624804 | T18: Set 2 24h | U18: nsP3 | V18: 19.470672 | W18: 19.791472 | X18: 0.52771699 | Y18: 2.44578 | Z18: 0.18354682 | AC18: Set 4 24h | AD18: nsP3 | AE18: 19.517558 | AF18: 19.396314 | AG18: 0.15855548 | AH18: 2.0766185 | AI18: 0.23706943 | AL18: Set 5 24h | AM18: nsP3 | AN18: 18.605618 | AO18: 18.605618 | AP18: -0.63214016 | AQ18: 1.2859228 | AR18: 0.41010839 | AU18: GFP 24h | AV18: nsP3 | AW18: 17.210057 | AX18: 17.638862 | AY18: -0.93175957 | AZ18: 0.98630342 | BA18: 0.50476948
C19: nsP3 | D19: 18.819592 | K19: Set 1 24h | L19: nsP3 | M19: 19.699336 | T19: Set 2 24h | U19: nsP3 | V19: 19.98383 | AC19: Set 4 24h | AD19: nsP3 | AE19: 19.22615 | AL19: Set 5 24h | AM19: nsP3 | AU19: GFP 24h | AV19: nsP3 | AW19: 17.842126
C20: nsP3 | K20: Set 1 24h | L20: nsP3 | M20: 19.803927 | T20: Set 2 24h | U20: nsP3 | V20: 19.919913 | AC20: Set 4 24h | AD20: nsP3 | AE20: 19.445232 | AL20: Set 5 24h | AM20: nsP3 | AU20: GFP 24h | AV20: nsP3 | AW20: 17.864404
A21: Gene 2 | B21: =C21 -> GFP | C21: GFP | E21: =AVERAGE(D21:D23) -> 16.943589 | F21: =E21-E3 -> -3.5279845 | G21: =AVERAGE(F21:F29) -> -3.448338 | H21: =F21-G21 -> -0.07964644 | I21: =2^-(H21) -> 1.056759 | K21: Set 1 24h | L21: GFP | M21: 16.6008 | N21: 16.6008 | O21: -2.9206731 | P21: 0.52766497 | Q21: 0.69367656 | T21: Set 2 24h | U21: GFP | V21: 15.922191 | W21: 15.773217 | X21: -1.7563826 | Y21: 1.6919555 | Z21: 0.30950713 | AC21: Set 4 24h | AD21: GFP | AE21: 16.84105 | AF21: 17.183717 | AG21: -3.18459 | AH21: 0.26374803 | AI21: 0.83292123 | AL21: Set 5 24h | AM21: GFP | AO21: 16.070528 | AP21: -4.2977785 | AQ21: -0.84944043 | AR21: 1.8018019 | AU21: GFP 24h | AV21: GFP | AW21: 17.881815 | AX21: 17.753016 | AY21: -0.13912975 | AZ21: 3.3092083 | BA21: 0.10088557
C22: GFP | D22: 16.943589 | K22: Set 1 24h | L22: GFP | T22: Set 2 24h | U22: GFP | V22: 15.811654 | AC22: Set 4 24h | AD22: GFP | AE22: 17.676383 | AL22: Set 5 24h | AM22: GFP | AU22: GFP 24h | AV22: GFP | AW22: 17.882134
C23: GFP | K23: Set 1 24h | L23: GFP | T23: Set 2 24h | U23: GFP | V23: 15.585807 | AC23: Set 4 24h | AD23: GFP | AE23: 17.033716 | AL23: Set 5 24h | AM23: GFP | AN23: 16.070528 | AU23: GFP 24h | AV23: GFP | AW23: 17.495099
C24: GFP | D24: 16.977031 | E24: =AVERAGE(D24:D26) -> 17.116928 | F24: =E24-E6 -> -3.546183 | H24: =F24-G21 -> -0.097844968 | I24: =2^-(H24) -> 1.0701737 | K24: Set 1 24h | L24: GFP | N24: 16.074471 | O24: -1.5742382 | P24: 1.8740999 | Q24: 0.27279708 | T24: Set 2 24h | U24: GFP | V24: 16.128999 | W24: 16.041095 | X24: -1.8176326 | Y24: 1.6307054 | Z24: 0.32293026 | AC24: Set 4 24h | AD24: GFP | AE24: 17.051925 | AF24: 17.080362 | AG24: -3.2404827 | AH24: 0.20785538 | AI24: 0.86582335 | AL24: Set 5 24h | AM24: GFP | AN24: 17.353568 | AO24: 17.353568 | AP24: -2.9672768 | AQ24: 0.48106126 | AR24: 0.7164504 | AU24: GFP 24h | AV24: GFP | AW24: 17.10497 | AX24: 17.155894 | AY24: -1.3065985 | AZ24: 2.1417395 | BA24: 0.22660639
C25: GFP | D25: 17.030316 | K25: Set 1 24h | L25: GFP | T25: Set 2 24h | U25: GFP | V25: 16.086532 | AC25: Set 4 24h | AD25: GFP | AE25: 17.06213 | AL25: Set 5 24h | AM25: GFP | AU25: GFP 24h | AV25: GFP | AW25: 17.341916
C26: GFP | D26: 17.343436 | K26: Set 1 24h | L26: GFP | M26: 16.074471 | T26: Set 2 24h | U26: GFP | V26: 15.907756 | AC26: Set 4 24h | AD26: GFP | AE26: 17.127031 | AL26: Set 5 24h | AM26: GFP | AU26: GFP 24h | AV26: GFP | AW26: 17.020795
C27: GFP | D27: 17.335388 | E27: =AVERAGE(D27:D29) -> 17.335388 | F27: =E27-E9 -> -3.2708466 | H27: =F27-G21 -> 0.17749141 | I27: =2^-(H27) -> 0.8842392 | K27: Set 1 24h | L27: GFP | N27: 17.143927 | O27: -2.0978903 | P27: 1.3504478 | Q27: 0.39217031 | T27: Set 2 24h | U27: GFP | V27: 17.518759 | W27: 17.511464 | X27: -1.7522902 | Y27: 1.6960479 | Z27: 0.30863041 | AC27: Set 4 24h | AD27: GFP | AE27: 16.316158 | AF27: 16.183707 | AG27: -3.0540516 | AH27: 0.3942864 | AI27: 0.76086563 | AL27: Set 5 24h | AM27: GFP | AO27: 16.596312 | AP27: -2.6414462 | AQ27: 0.80689188 | AR27: 0.571612 | AU27: GFP 24h | AV27: GFP | AW27: 17.68024 | AX27: 17.653169 | AY27: -0.91745273 | AZ27: 2.5308853 | BA27: 0.17303247
C28: GFP | K28: Set 1 24h | L28: GFP | M28: 17.143927 | T28: Set 2 24h | U28: GFP | V28: 17.499384 | AC28: Set 4 24h | AD28: GFP | AE28: 16.177653 | AL28: Set 5 24h | AM28: GFP | AU28: GFP 24h | AV28: GFP | AW28: 17.747487
C29: GFP | K29: Set 1 24h | L29: GFP | T29: Set 2 24h | U29: GFP | V29: 17.51625 | AC29: Set 4 24h | AD29: GFP | AE29: 16.057309 | AL29: Set 5 24h | AM29: GFP | AN29: 16.596312 | AU29: GFP 24h | AV29: GFP | AW29: 17.531779
A30: Gene 3 | B30: =C30 -> RIG1 | C30: RIG1 | D30: 23.476037 | E30: =AVERAGE(D30:D32) -> 23.163158 | F30: =E30-E3 -> 2.6915848 | G30: =AVERAGE(F30:F38) -> 2.6314182 | H30: =F30-G30 -> 0.060166585 | I30: =2^-(H30) -> 0.95915336 | K30: Set 1 24h | L30: RIG1 | M30: 24.460534 | N30: 24.687106 | O30: 5.1656323 | P30: 2.5342141 | Q30: 0.17263369 | T30: Set 2 24h | U30: RIG1 | V30: 22.166063 | W30: 22.456962 | X30: 4.9273621 | Y30: 2.2959439 | Z30: 0.20363481 | AC30: Set 4 24h | AD30: RIG1 | AE30: 25.472786 | AF30: 25.678378 | AG30: 5.3100718 | AH30: 2.6786537 | AI30: 0.15618701 | AL30: Set 5 24h | AM30: RIG1 | AO30: 23.872664 | AP30: 3.504357 | AQ30: 0.87293879 | AR30: 0.54603344 | AU30: GFP 24h | AV30: RIG1 | AW30: 18.612327 | AX30: 20.316362 | AY30: 2.4242158 | AZ30: -0.20720242 | BA30: 1.1544474
C31: Rig1 | D31: 22.869573 | K31: Set 1 24h | L31: Rig1 | M31: 24.813533 | T31: Set 2 24h | U31: Rig1 | V31: 22.594613 | AC31: Set 4 24h | AD31: Rig1 | AE31: 25.41077 | AL31: Set 5 24h | AM31: Rig1 | AN31: 23.872664 | AU31: GFP 24h | AV31: Rig1 | AW31: 20.891992
C32: RIG1 | D32: 23.143864 | K32: Set 1 24h | L32: RIG1 | M32: 24.787249 | T32: Set 2 24h | U32: RIG1 | V32: 22.61021 | AC32: Set 4 24h | AD32: RIG1 | AE32: 26.151579 | AL32: Set 5 24h | AM32: RIG1 | AU32: GFP 24h | AV32: RIG1 | AW32: 21.444767
C33: RIG1 | D33: 22.517454 | E33: =AVERAGE(D33:D35) -> 23.159823 | F33: =E33-E6 -> 2.4967126 | H33: =F33-G30 -> -0.13470561 | I33: =2^-(H33) -> 1.0978688 | K33: Set 1 24h | L33: RIG1 | M33: 23.405031 | N33: 23.058127 | O33: 5.409418 | P33: 2.7779998 | Q33: 0.14579369 | T33: Set 2 24h | U33: RIG1 | V33: 23.192043 | W33: 22.837376 | X33: 4.9786479 | Y33: 2.3472297 | Z33: 0.19652303 | AC33: Set 4 24h | AD33: RIG1 | AE33: 25.275397 | AF33: 25.101688 | AG33: 4.7808428 | AH33: 2.1494246 | AI33: 0.22540249 | AL33: Set 5 24h | AM33: RIG1 | AO33: 25.164878 | AP33: 4.8440329 | AQ33: 2.2126147 | AR33: 0.21574294 | AU33: GFP 24h | AV33: RIG1 | AW33: 21.342363 | AX33: 20.844306 | AY33: 2.3818135 | AZ33: -0.24960468 | BA33: 1.1888813
C34: RIG1 | K34: Set 1 24h | L34: RIG1 | M34: 22.860995 | T34: Set 2 24h | U34: RIG1 | V34: 22.731146 | AC34: Set 4 24h | AD34: RIG1 | AE34: 24.948784 | AL34: Set 5 24h | AM34: RIG1 | AN34: 25.164878 | AU34: GFP 24h | AV34: RIG1 | AW34: 20.810301
C35: RIG1 | D35: 23.802193 | K35: Set 1 24h | L35: RIG1 | M35: 22.908355 | T35: Set 2 24h | U35: RIG1 | V35: 22.588939 | AC35: Set 4 24h | AD35: RIG1 | AE35: 25.080881 | AL35: Set 5 24h | AM35: RIG1 | AU35: GFP 24h | AV35: RIG1 | AW35: 20.380253
C36: RIG1 | D36: 23.312192 | E36: =AVERAGE(D36:D38) -> 23.312192 | F36: =E36-E9 -> 2.7059572 | H36: =F36-G30 -> 0.074539027 | I36: =2^-(H36) -> 0.9496455 | K36: Set 1 24h | L36: RIG1 | M36: 23.888905 | N36: 24.327915 | O36: 5.086098 | P36: 2.4546798 | Q36: 0.18241802 | T36: Set 2 24h | U36: RIG1 | V36: 23.489882 | W36: 24.055426 | X36: 4.7916718 | Y36: 2.1602537 | Z36: 0.22371693 | AC36: Set 4 24h | AD36: RIG1 | AE36: 24.107455 | AF36: 24.533775 | AG36: 5.2960172 | AH36: 2.664599 | AI36: 0.157716 | AL36: Set 5 24h | AM36: RIG1 | AO36: 23.900992 | AP36: 4.6632339 | AQ36: 2.0318157 | AR36: 0.2445471 | AU36: GFP 24h | AV36: RIG1 | AW36: 20.902436 | AX36: 21.015581 | AY36: 2.4449598 | AZ36: -0.18645843 | BA36: 1.1379668
C37: RIG1 | K37: Set 1 24h | L37: RIG1 | M37: 24.240997 | T37: Set 2 24h | U37: RIG1 | V37: 23.826281 | AC37: Set 4 24h | AD37: RIG1 | AE37: 24.719999 | AL37: Set 5 24h | AM37: RIG1 | AN37: 23.900992 | AU37: GFP 24h | AV37: RIG1 | AW37: 20.709475
C38: RIG1 | K38: Set 1 24h | L38: RIG1 | M38: 24.853844 | T38: Set 2 24h | U38: RIG1 | V38: 24.850117 | AC38: Set 4 24h | AD38: RIG1 | AE38: 24.773872 | AL38: Set 5 24h | AM38: RIG1 | AU38: GFP 24h | AV38: RIG1 | AW38: 21.434833
A39: Gene 4 | B39: =C39 -> MDA5 | C39: MDA5 | E39: =AVERAGE(D39:D41) -> 25.793674 | F39: =E39-E3 -> 5.3221012 | G39: =AVERAGE(F39:F47) -> 5.2591612 | H39: =F39-G39 -> 0.062940009 | I39: =2^-(H39) -> 0.95731126 | K39: Set 1 24h | L39: MDA5 | M39: 27.465806 | N39: 27.715893 | O39: 8.1944198 | P39: 2.9352586 | Q39: 0.13073718 | T39: Set 2 24h | U39: MDA5 | V39: 24.127261 | W39: 24.638742 | X39: 7.1091418 | Y39: 1.8499806 | Z39: 0.2773961 | AC39: Set 4 24h | AD39: MDA5 | AE39: 29.784446 | AF39: 29.925614 | AG39: 9.5573075 | AH39: 4.2981463 | AI39: 0.050831044 | AL39: Set 5 24h | AM39: MDA5 | AN39: 28.379429 | AO39: 28.858995 | AP39: 8.4906889 | AQ39: 3.2315277 | AR39: 0.10646656 | AU39: GFP 24h | AV39: MDA5 | AW39: 22.486447 | AX39: 22.112681 | AY39: 4.2205352 | AZ39: -1.038626 | BA39: 2.0542703
C40: MDA5 | D40: 25.793674 | K40: Set 1 24h | L40: MDA5 | M40: 27.874627 | T40: Set 2 24h | U40: MDA5 | V40: 24.968374 | AC40: Set 4 24h | AD40: MDA5 | AE40: 29.625948 | AL40: Set 5 24h | AM40: MDA5 | AN40: 28.779788 | AU40: GFP 24h | AV40: MDA5 | AW40: 21.486816
...

Sheet Sheet2

Sheet Calculations_1
E3: WT 24h | Q3: Set 1 24h | AB3: Set 2 24h | AM3: Set 4 24h | AX3: Set 5 24h | BI3: GFP 24h
E4: Well Position | F4: Sample | G4: Target | H4: Cq | Q4: Well Position | R4: Sample | S4: Target | T4: Cq | AB4: Well Position | AC4: Sample | AD4: Target | AE4: Cq | AM4: Well Position | AN4: Sample | AO4: Target | AP4: Cq | AX4: Well Position | AY4: Sample | AZ4: Target | BA4: Cq | BI4: Well Position | BJ4: Sample | BK4: Target | BL4: Cq
W14: Colours to use: | AH14: Colours to use: | AS14: Colours to use: | BD14: Colours to use:
K15: Colours to use: | X15: GAPDH | Y15: nsP3 | AI15: GAPDH | AJ15: nsP3 | AT15: GAPDH | AU15: nsP3 | BE15: GAPDH | BF15: nsP3
L16: GAPDH | M16: nsP3 | W16: Exported info | AH16: Exported info | AS16: Exported info | BD16: Exported info
K17: Exported info | W17: Exported Alt | AH17: Exported Alt | AS17: Exported Alt | BD17: Exported Alt
K18: Exported Alt | W18: Avg Cq | AH18: Avg Cq | AS18: Avg Cq | BD18: Avg Cq
K19: Avg Cq | W19: ∆Cq | AH19: ∆Cq | AS19: ∆Cq | BD19: ∆Cq
K20: ∆Cq | W20: ∆∆Cq | AH20: ∆∆Cq | AS20: ∆∆Cq | BD20: ∆∆Cq
K21: ∆∆Cq | W21: 2-∆∆Cq | AH21: 2-∆∆Cq | AS21: 2-∆∆Cq | BD21: 2-∆∆Cq
K22: 2-∆∆Cq | X22: GFP | Y22: RIG1 | AI22: GFP | AJ22: RIG1 | AT22: GFP | AU22: RIG1 | BE22: GFP | BF22: RIG1
L23: GFP | M23: RIG1 | W23: Exported info | AH23: Exported info | AS23: Exported info | BD23: Exported info
K24: Exported info | W24: Exported Alt | AH24: Exported Alt | AS24: Exported Alt | BD24: Exported Alt
K25: Exported Alt | W25: Avg Cq | AH25: Avg Cq | AS25: Avg Cq | BD25: Avg Cq
K26: Avg Cq | W26: ∆Cq | AH26: ∆Cq | AS26: ∆Cq | BD26: ∆Cq
K27: ∆Cq | W27: ∆∆Cq | AH27: ∆∆Cq | AS27: ∆∆Cq | BD27: ∆∆Cq
K28: ∆∆Cq | W28: 2-∆∆Cq | AH28: 2-∆∆Cq | AS28: 2-∆∆Cq | BD28: 2-∆∆Cq
K29: 2-∆∆Cq | X29: MDA5 | Y29: IFIT | AI29: MDA5 | AJ29: IFIT | AT29: MDA5 | AU29: IFIT | BE29: MDA5 | BF29: IFIT
L30: MDA5 | M30: IFIT | W30: Exported info | AH30: Exported info | AS30: Exported info | BD30: Exported info
K31: Exported info | W31: Exported Alt | AH31: Exported Alt | AS31: Exported Alt | BD31: Exported Alt
K32: Exported Alt | W32: Avg Cq | AH32: Avg Cq | AS32: Avg Cq | BD32: Avg Cq
K33: Avg Cq | W33: ∆Cq | AH33: ∆Cq | AS33: ∆Cq | BD33: ∆Cq
K34: ∆Cq | W34: ∆∆Cq | AH34: ∆∆Cq | AS34: ∆∆Cq | BD34: ∆∆Cq
K35: ∆∆Cq | W35: 2-∆∆Cq | AH35: 2-∆∆Cq | AS35: 2-∆∆Cq | BD35: 2-∆∆Cq
K36: 2-∆∆Cq | W36: Undetermined | AH36: Undetermined | AS36: Undetermined | BD36: Undetermined
K37: Undetermined
C43: =E3 -> WT 24h | O43: =Q3 -> Set 1 24h | Z43: =AB3 -> Set 2 24h | AK43: =AM3 -> Set 4 24h | AV43: =AX3 -> Set 5 24h | BG43: =BI3 -> GFP 24h
C44: Well Position | D44: Sample | E44: Target | F44: Cq | G44: Avg Cq | H44: ∆Cq | I44: Avg ∆Cq | J44: ∆∆Cq | K44: 2-∆∆Cq | O44: Well Position | P44: Sample | Q44: Target | R44: Cq | S44: Avg Cq | T44: ∆Cq | U44: ∆∆Cq | V44: 2-∆∆Cq | Z44: Well Position | AA44: Sample | AB44: Target | AC44: Cq | AD44: Avg Cq | AE44: ∆Cq | AF44: ∆∆Cq | AG44: 2-∆∆Cq | AK44: Well Position | AL44: Sample | AM44: Target | AN44: Cq | AO44: Avg Cq | AP44: ∆Cq | AQ44: ∆∆Cq | AR44: 2-∆∆Cq | AV44: Well Position | AW44: Sample | AX44: Target | AY44: Cq | AZ44: Avg Cq | BA44: ∆Cq | BB44: ∆∆Cq | BC44: 2-∆∆Cq | BG44: Well Position | BH44: Sample | BI44: Target | BJ44: Cq | BK44: Avg Cq | BL44: ∆Cq | BM44: ∆∆Cq | BN44: 2-∆∆Cq
A45: Housekeeping Gene | B45: =E45 -> GAPDH | D45: =$C$43 -> WT 24h | E45: GAPDH | F45: 20.427816 | G45: =AVERAGE(F45:F47) -> 20.471573 | P45: =$O$43 -> Set 1 24h | Q45: GAPDH | R45: 19.593802 | S45: =AVERAGE(R45:R47) -> 19.521473 | AA45: =$Z$43 -> Set 2 24h | AB45: GAPDH | AC45: 17.46995 | AD45: =AVERAGE(AC45:AC47) -> 17.5296 | AL45: =$AK$43 -> Set 4 24h | AM45: GAPDH | AN45: 20.722142 | AO45: =AVERAGE(AN45:AN47) -> 20.368307 | AW45: =$AV$43 -> Set 5 24h | AX45: GAPDH | AY45: 20.722142 | AZ45: =AVERAGE(AY45:AY47) -> 20.368307 | BH45: =$BG$43 -> GFP 24h | BI45: GAPDH | BK45: =AVERAGE(BJ45:BJ47) -> 17.892146
D46: =$C$43 -> WT 24h | E46: GAPDH | P46: =$O$43 -> Set 1 24h | Q46: GAPDH | R46: 19.382193 | AA46: =$Z$43 -> Set 2 24h | AB46: GAPDH | AC46: 17.578786 | AL46: =$AK$43 -> Set 4 24h | AM46: GAPDH | AN46: 19.967785 | AW46: =$AV$43 -> Set 5 24h | AX46: GAPDH | AY46: 19.967785 | BH46: =$BG$43 -> GFP 24h | BI46: GAPDH | BJ46: 17.845502
D47: =$C$43 -> WT 24h | E47: GAPDH | F47: 20.51533 | P47: =$O$43 -> Set 1 24h | Q47: GAPDH | R47: 19.588425 | AA47: =$Z$43 -> Set 2 24h | AB47: GAPDH | AC47: 17.540063 | AL47: =$AK$43 -> Set 4 24h | AM47: GAPDH | AN47: 20.414992 | AW47: =$AV$43 -> Set 5 24h | AX47: GAPDH | AY47: 20.414992 | BH47: =$BG$43 -> GFP 24h | BI47: GAPDH | BJ47: 17.93879
D48: =$C$43 -> WT 24h | E48: GAPDH | G48: =AVERAGE(F48:F50) -> 20.663111 | P48: =$O$43 -> Set 1 24h | Q48: GAPDH | R48: 17.611369 | S48: =AVERAGE(R48:R50) -> 17.648709 | AA48: =$Z$43 -> Set 2 24h | AB48: GAPDH | AC48: 17.707659 | AD48: =AVERAGE(AC48:AC50) -> 17.858728 | AL48: =$AK$43 -> Set 4 24h | AM48: GAPDH | AN48: 20.630732 | AO48: =AVERAGE(AN48:AN50) -> 20.320845 | AW48: =$AV$43 -> Set 5 24h | AX48: GAPDH | AY48: 20.630732 | AZ48: =AVERAGE(AY48:AY50) -> 20.320845 | BH48: =$BG$43 -> GFP 24h | BI48: GAPDH | BJ48: 18.315127 | BK48: =AVERAGE(BJ48:BJ50) -> 18.462492
D49: =$C$43 -> WT 24h | E49: GAPDH | F49: 20.71529 | P49: =$O$43 -> Set 1 24h | Q49: GAPDH | R49: 17.628815 | AA49: =$Z$43 -> Set 2 24h | AB49: GAPDH | AC49: 17.8579 | AL49: =$AK$43 -> Set 4 24h | AM49: GAPDH | AN49: 20.256084 | AW49: =$AV$43 -> Set 5 24h | AX49: GAPDH | AY49: 20.256084 | BH49: =$BG$43 -> GFP 24h | BI49: GAPDH | BJ49: 18.536358
D50: =$C$43 -> WT 24h | E50: GAPDH | F50: 20.610931 | P50: =$O$43 -> Set 1 24h | Q50: GAPDH | R50: 17.705944 | AA50: =$Z$43 -> Set 2 24h | AB50: GAPDH | AC50: 18.010625 | AL50: =$AK$43 -> Set 4 24h | AM50: GAPDH | AN50: 20.075719 | AW50: =$AV$43 -> Set 5 24h | AX50: GAPDH | AY50: 20.075719 | BH50: =$BG$43 -> GFP 24h | BI50: GAPDH | BJ50: 18.535992
D51: =$C$43 -> WT 24h | E51: GAPDH | F51: 20.672207 | G51: =AVERAGE(F51:F53) -> 20.606235 | P51: =$O$43 -> Set 1 24h | Q51: GAPDH | R51: 19.22486 | S51: =AVERAGE(R51:R53) -> 19.241817 | AA51: =$Z$43 -> Set 2 24h | AB51: GAPDH | AC51: 19.328557 | AD51: =AVERAGE(AC51:AC53) -> 19.263755 | AL51: =$AK$43 -> Set 4 24h | AM51: GAPDH | AN51: 19.142668 | AO51: =AVERAGE(AN51:AN53) -> 19.237758 | AW51: =$AV$43 -> Set 5 24h | AX51: GAPDH | AY51: 19.142668 | AZ51: =AVERAGE(AY51:AY53) -> 19.237758 | BH51: =$BG$43 -> GFP 24h | BI51: GAPDH | BJ51: 18.483091 | BK51: =AVERAGE(BJ51:BJ53) -> 18.570622
D52: =$C$43 -> WT 24h | E52: GAPDH | P52: =$O$43 -> Set 1 24h | Q52: GAPDH | R52: 19.644558 | AA52: =$Z$43 -> Set 2 24h | AB52: GAPDH | AC52: 19.610464 | AL52: =$AK$43 -> Set 4 24h | AM52: GAPDH | AN52: 19.318447 | AW52: =$AV$43 -> Set 5 24h | AX52: GAPDH | AY52: 19.318447 | BH52: =$BG$43 -> GFP 24h | BI52: GAPDH | BJ52: 18.980717
D53: =$C$43 -> WT 24h | E53: GAPDH | F53: 20.540263 | P53: =$O$43 -> Set 1 24h | Q53: GAPDH | R53: 18.856033 | AA53: =$Z$43 -> Set 2 24h | AB53: GAPDH | AC53: 18.852243 | AL53: =$AK$43 -> Set 4 24h | AM53: GAPDH | AN53: 19.252159 | AW53: =$AV$43 -> Set 5 24h | AX53: GAPDH | AY53: 19.252159 | BH53: =$BG$43 -> GFP 24h | BI53: GAPDH | BJ53: 18.248058
A54: Gene 1 | B54: =E54 -> nsP3 | D54: =$C$43 -> WT 24h | E54: nsP3 | G54: =AVERAGE(F54:F56) -> 18.462688 | H54: =G54-G45 -> -2.0088851 | I54: =AVERAGE(H54:H62) -> -1.918063 | J54: =H54-I54 -> -0.090822117 | K54: =2^-(J54) -> 1.0649769 | P54: =$O$43 -> Set 1 24h | Q54: nsP3 | R54: 19.075895 | S54: =AVERAGE(R54:R56) -> 18.867162 | T54: =S54-S45 -> -0.65431147 | U54: =T54-I54 -> 1.2637515 | V54: =2^-(U54) -> 0.41645961 | AA54: =$Z$43 -> Set 2 24h | AB54: nsP3 | AC54: 18.231773 | AD54: =AVERAGE(AC54:AC56) -> 18.070737 | AE54: =AD54-AD45 -> 0.54113764 | AF54: =AE54-I54 -> 2.4592006 | AG54: =2^-(AF54) -> 0.1818473 | AL54: =$AK$43 -> Set 4 24h | AM54: nsP3 | AN54: 20.782261 | AO54: =AVERAGE(AN54:AN56) -> 20.708842 | AP54: =AO54-AO45 -> 0.3405353 | AQ54: =AP54-I54 -> 2.2585983 | AR54: =2^-(AQ54) -> 0.20897492 | AW54: =$AV$43 -> Set 5 24h | AX54: nsP3 | AZ54: =AVERAGE(AY54:AY56) -> 18.88954 | BA54: =AZ54-AZ45 -> -1.4787667 | BB54: =BA54-I54 -> 0.43929626 | BC54: =2^-(BB54) -> 0.73749427 | BH54: =$BG$43 -> GFP 24h | BI54: nsP3 | BJ54: 17.757053 | BK54: =AVERAGE(BJ54:BJ56) -> 17.463924 | BL54: =BK54-BK45 -> -0.42822189 | BM54: =BL54-I54 -> 1.4898411 | BN54: =2^-(BM54) -> 0.35605176
D55: =$C$43 -> WT 24h | E55: nsP3 | P55: =$O$43 -> Set 1 24h | Q55: nsP3 | R55: 18.406874 | AA55: =$Z$43 -> Set 2 24h | AB55: nsP3 | AC55: 17.814543 | AL55: =$AK$43 -> Set 4 24h | AM55: nsP3 | AN55: 20.611873 | AW55: =$AV$43 -> Set 5 24h | AX55: nsP3 | BH55: =$BG$43 -> GFP 24h | BI55: nsP3 | BJ55: 17.049854
D56: =$C$43 -> WT 24h | E56: nsP3 | F56: 18.462688 | P56: =$O$43 -> Set 1 24h | Q56: nsP3 | R56: 19.118717 | AA56: =$Z$43 -> Set 2 24h | AB56: nsP3 | AC56: 18.165897 | AL56: =$AK$43 -> Set 4 24h | AM56: nsP3 | AN56: 20.732391 | AW56: =$AV$43 -> Set 5 24h | AX56: nsP3 | AY56: 18.88954 | BH56: =$BG$43 -> GFP 24h | BI56: nsP3 | BJ56: 17.584865
...

Sheet Bar Graphs_1
B11: Individual Genes | U11: All Genes
C13: Gene 1
C14: =Calculations_1!B54 -> nsP3
C15: Sample | D15: 2-∆∆Cq | E15: Avg. 2-∆∆Cq | F15: Std. Dev 2-∆∆Cq | H15: =(B16) & "x" -> WT 24hx | I15: =B16 -> WT 24h | J15: =B19 & "x" -> Set 1 24hx | K15: =B19 -> Set 1 24h | L15: =B22 & "x" -> Set 2 24hx | M15: =B22 -> Set 2 24h | N15: =B25 & "x" -> Set 4 24hx | O15: =B25 -> Set 4 24h | P15: =B28 & "x" -> Set 5 24hx | Q15: =B28 -> Set 5 24h | R15: =B31 & "x" -> GFP 24hx | S15: =B31 -> GFP 24h
B16: =Calculations_1!E3 -> WT 24h | C16: =Calculations_1!D54 -> WT 24h | D16: =Calculations_1!K54 -> 1.0649769 | E16: =AVERAGE(D16:D18) -> 1.0021498 | F16: =STDEV(D16:D18) -> 0.079383298 | H16: 1.002 | I16: =D16 -> 1.0649769 | J16: 2.002 | K16: =D19 -> 0.41645961 | L16: 3.002 | M16: =D22 -> 0.1818473 | N16: 4.002 | O16: =D25 -> 0.20897492 | P16: 5.002 | Q16: =D28 -> 0.73749427 | R16: 6.002 | S16: =D31 -> 0.35605176
C17: =Calculations_1!D57 -> WT 24h | D17: =Calculations_1!K57 -> 1.02854 | H17: 1.002 | I17: =D17 -> 1.02854 | J17: 2.002 | K17: =D20 -> 0.22882517 | L17: 3.002 | M17: =D23 -> 0.28511557 | N17: 4.002 | O17: =D26 -> 0.19003516 | P17: 5.002 | Q17: =D29 -> 0.59975175 | R17: 6.002 | S17: =D32 -> 0.71031173 | U17: Avg. 2-∆∆Cq | AD17: Std. Dev 2-∆∆Cq
C18: =Calculations_1!D60 -> WT 24h | D18: =Calculations_1!K60 -> 0.91293246 | H18: 1.002 | I18: =D18 -> 0.91293246 | J18: 2.002 | K18: =D21 -> 0.22624804 | L18: 3.002 | M18: =D24 -> 0.18354682 | N18: 4.002 | O18: =D27 -> 0.23706943 | P18: 5.002 | Q18: =D30 -> 0.41010839 | R18: 6.002 | S18: =D33 -> 0.50476948 | W18: =Calculations_1!E3 -> WT 24h | X18: =Calculations_1!Q3 -> Set 1 24h | Y18: =Calculations_1!AB3 -> Set 2 24h | Z18: =Calculations_1!AM3 -> Set 4 24h | AA18: =Calculations_1!AX3 -> Set 5 24h | AB18: =Calculations_1!BI3 -> GFP 24h | AF18: =Calculations_1!E3 -> WT 24h | AG18: =Calculations_1!Q3 -> Set 1 24h | AH18: =Calculations_1!AB3 -> Set 2 24h | AI18: =Calculations_1!AM3 -> Set 4 24h | AJ18: =Calculations_1!AX3 -> Set 5 24h | AK18: =Calculations_1!BI3 -> GFP 24h
B19: =Calculations_1!Q3 -> Set 1 24h | C19: =Calculations_1!P54 -> Set 1 24h | D19: =Calculations_1!V54 -> 0.41645961 | E19: =AVERAGE(D19:D21) -> 0.29051094 | F19: =STDEV(D19:D21) -> 0.10908236 | U19: Gene 1 | V19: =C14 -> nsP3 | W19: =I21 -> 1.0021498 | X19: =J21 -> 0.29051094 | Y19: =K21 -> 0.21683656 | Z19: =L21 -> 0.2120265 | AA19: =M21 -> 0.58245147 | AB19: =N21 -> 0.52371099 | AD19: Gene 1 | AE19: =C14 -> nsP3 | AF19: =I22 -> 0.079383298 | AG19: =J22 -> 0.10908236 | AH19: =K22 -> 0.059137461 | AI19: =L22 -> 0.023665159 | AJ19: =M22 -> 0.16437716 | AK19: =N22 -> 0.17788793
C20: =Calculations_1!P57 -> Set 1 24h | D20: =Calculations_1!V57 -> 0.22882517 | I20: =B16 -> WT 24h | J20: =B19 -> Set 1 24h | K20: =B22 -> Set 2 24h | L20: =B25 -> Set 4 24h | M20: =B28 -> Set 5 24h | N20: =B31 -> GFP 24h | U20: Gene 2 | V20: =C54 -> GFP | W20: =I61 -> 1.003724 | X20: =J61 -> 0.45288132 | Y20: =K61 -> 0.31368927 | Z20: =L61 -> 0.81987007 | AA20: =M61 -> 1.0299548 | AB20: =N61 -> 0.16684148 | AD20: Gene 2 | AE20: =C54 -> GFP | AF20: =I62 -> 0.10369401 | AG20: =J62 -> 0.2169084 | AH20: =K62 -> 0.008014935 | AI20: =L62 -> 0.053682217 | AJ20: =M62 -> 0.67235078 | AK20: =N62 -> 0.063088649
C21: =Calculations_1!P60 -> Set 1 24h | D21: =Calculations_1!V60 -> 0.22624804 | H21: Avg. 2-∆∆Cq | I21: =E16 -> 1.0021498 | J21: =E19 -> 0.29051094 | K21: =E22 -> 0.21683656 | L21: =E25 -> 0.2120265 | M21: =E28 -> 0.58245147 | N21: =E31 -> 0.52371099 | U21: Gene 3 | V21: =C94 -> RIG1 | W21: =I101 -> 1.0022225 | X21: =J101 -> 0.16694847 | Y21: =K101 -> 0.20795825 | Z21: =L101 -> 0.1797685 | AA21: =M101 -> 0.33544116 | AB21: =N101 -> 1.1604318 | AD21: Gene 3 | AE21: =C94 -> RIG1 | AF21: =I102 -> 0.082968366 | AG21: =J102 -> 0.018962508 | AH21: =K102 -> 0.014103058 | AI21: =L102 -> 0.039527591 | AJ21: =M102 -> 0.18294603 | AK21: =N102 -> 0.02597946
B22: =Calculations_1!AB3 -> Set 2 24h | C22: =Calculations_1!AA54 -> Set 2 24h | D22: =Calculations_1!AG54 -> 0.1818473 | E22: =AVERAGE(D22:D24) -> 0.21683656 | F22: =STDEV(D22:D24) -> 0.059137461 | H22: Std. Dev 2-∆∆Cq | I22: =F16 -> 0.079383298 | J22: =F19 -> 0.10908236 | K22: =F22 -> 0.059137461 | L22: =F25 -> 0.023665159 | M22: =F28 -> 0.16437716 | N22: =F31 -> 0.17788793 | U22: Gene 4 | V22: =C134 -> MDA5 | W22: =I141 -> 1.0141266 | X22: =J141 -> 0.10527146 | Y22: =K141 -> 0.28758417 | Z22: =L141 -> 0.037186731 | AA22: =M141 -> 0.05338302 | AB22: =N141 -> 2.1024135 | AD22: Gene 4 | AE22: =C134 -> MDA5 | AF22: =I142 -> 0.21143867 | AG22: =J142 -> 0.039558395 | AH22: =K142 -> 0.041113971 | AI22: =L142 -> 0.01209565 | AJ22: =M142 -> 0.045971734 | AK22: =N142 -> 0.084450381
C23: =Calculations_1!AA57 -> Set 2 24h | D23: =Calculations_1!AG57 -> 0.28511557 | U23: Gene 5 | V23: =C174 -> IFIT | W23: =I181 -> 1.0078069 | X23: =J181 -> 0.24685267 | Y23: =K181 -> 0.60513266 | Z23: =L181 -> 0.31041229 | AA23: =M181 -> 0.30104997 | AB23: =N181 -> 2.0210197 | AD23: Gene 5 | AE23: =C174 -> IFIT | AF23: =I182 -> 0.15605652 | AG23: =J182 -> 0.081462642 | AH23: =K182 -> 0.1247813 | AI23: =L182 -> 0.11411621 | AJ23: =M182 -> 0.12035984 | AK23: =N182 -> 0.13014609
C24: =Calculations_1!AA60 -> Set 2 24h | D24: =Calculations_1!AG60 -> 0.18354682
B25: =Calculations_1!AM3 -> Set 4 24h | C25: =Calculations_1!AL54 -> Set 4 24h | D25: =Calculations_1!AR54 -> 0.20897492 | E25: =AVERAGE(D25:D27) -> 0.2120265 | F25: =STDEV(D25:D27) -> 0.023665159
C26: =Calculations_1!AL57 -> Set 4 24h | D26: =Calculations_1!AR57 -> 0.19003516
C27: =Calculations_1!AL60 -> Set 4 24h | D27: =Calculations_1!AR60 -> 0.23706943
B28: =Calculations_1!AX3 -> Set 5 24h | C28: =Calculations_1!AW54 -> Set 5 24h | D28: =Calculations_1!BC54 -> 0.73749427 | E28: =AVERAGE(D28:D30) -> 0.58245147 | F28: =STDEV(D28:D30) -> 0.16437716 | W28: =X28 & "x" -> WT 24hx | X28: =Calculations_1!E3 -> WT 24h | Y28: =Z28 & "x" -> Set 1 24hx | Z28: =Calculations_1!Q3 -> Set 1 24h | AA28: =AB28 & "x" -> Set 2 24hx | AB28: =Calculations_1!AB3 -> Set 2 24h | AC28: =AD28 & "x" -> Set 4 24hx | AD28: =Calculations_1!AM3 -> Set 4 24h | AE28: =AF28 & "x" -> Set 5 24hx | AF28: =Calculations_1!AX3 -> Set 5 24h | AG28: =AH28 & "x" -> GFP 24hx | AH28: =Calculations_1!BI3 -> GFP 24h
C29: =Calculations_1!AW57 -> Set 5 24h | D29: =Calculations_1!BC57 -> 0.59975175 | U29: Gene 1 | V29: =C14 -> nsP3 | W29: 0.6947 | X29: =I16 -> 1.0649769 | Y29: =W29+1 -> 1.6947 | Z29: =K16 -> 0.41645961 | AA29: =W29+2 -> 2.6947 | AB29: =M16 -> 0.1818473 | AC29: =3+W29 -> 3.6947 | AD29: =O16 -> 0.20897492 | AE29: =4+W29 -> 4.6947 | AF29: =Q16 -> 0.73749427 | AG29: =5+W29 -> 5.6947 | AH29: =S16 -> 0.35605176
C30: =Calculations_1!AW60 -> Set 5 24h | D30: =Calculations_1!BC60 -> 0.41010839 | W30: =W29 -> 0.6947 | X30: =I17 -> 1.02854 | Y30: =W30+1 -> 1.6947 | Z30: =K17 -> 0.22882517 | AA30: =W30+2 -> 2.6947 | AB30: =M17 -> 0.28511557 | AC30: =3+W30 -> 3.6947 | AD30: =O17 -> 0.19003516 | AE30: =4+W30 -> 4.6947 | AF30: =Q17 -> 0.59975175 | AG30: =5+W30 -> 5.6947 | AH30: =S17 -> 0.71031173
B31: =Calculations_1!BI3 -> GFP 24h | C31: =Calculations_1!BH54 -> GFP 24h | D31: =Calculations_1!BN54 -> 0.35605176 | E31: =AVERAGE(D31:D33) -> 0.52371099 | F31: =STDEV(D31:D33) -> 0.17788793 | W31: =W29 -> 0.6947 | X31: =I18 -> 0.91293246 | Y31: =W31+1 -> 1.6947 | Z31: =K18 -> 0.22624804 | AA31: =W31+2 -> 2.6947 | AB31: =M18 -> 0.18354682 | AC31: =3+W31 -> 3.6947 | AD31: =O18 -> 0.23706943 | AE31: =4+W31 -> 4.6947 | AF31: =Q18 -> 0.41010839 | AG31: =5+W31 -> 5.6947 | AH31: =S18 -> 0.50476948
C32: =Calculations_1!BH57 -> GFP 24h | D32: =Calculations_1!BN57 -> 0.71031173 | U32: Gene 2 | V32: =C54 -> GFP | W32: 0.8479 | X32: =I56 -> 1.056759 | Y32: =W32+1 -> 1.8479 | Z32: =K56 -> 0.69367656 | AA32: =W32+2 -> 2.8479 | AB32: =M56 -> 0.30950713 | AC32: =3+W32 -> 3.8479 | AD32: =O56 -> 0.83292123 | AE32: =4+W32 -> 4.8479 | AF32: =Q56 -> 1.8018019 | AG32: =5+W32 -> 5.8479 | AH32: =S56 -> 0.10088557
C33: =Calculations_1!BH60 -> GFP 24h | D33: =Calculations_1!BN60 -> 0.50476948 | W33: =W32 -> 0.8479 | X33: =I57 -> 1.0701737 | Y33: =W33+1 -> 1.8479 | Z33: =K57 -> 0.27279708 | AA33: =W33+2 -> 2.8479 | AB33: =M57 -> 0.32293026 | AC33: =3+W33 -> 3.8479 | AD33: =O57 -> 0.86582335 | AE33: =4+W33 -> 4.8479 | AF33: =Q57 -> 0.7164504 | AG33: =5+W33 -> 5.8479 | AH33: =S57 -> 0.22660639
W34: =W32 -> 0.8479 | X34: =I58 -> 0.8842392 | Y34: =W34+1 -> 1.8479 | Z34: =K58 -> 0.39217031 | AA34: =2+W34 -> 2.8479 | AB34: =M58 -> 0.30863041 | AC34: =3+W34 -> 3.8479 | AD34: =O58 -> 0.76086563 | AE34: =4+W34 -> 4.8479 | AF34: =Q58 -> 0.571612 | AG34: =5+W34 -> 5.8479 | AH34: =S58 -> 0.17303247
U35: Gene 3 | V35: =C94 -> RIG1 | W35: 1 | X35: =I96 -> 0.95915336 | Y35: =W35+1 -> 2 | Z35: =K96 -> 0.17263369 | AA35: =2+W35 -> 3 | AB35: =M96 -> 0.20363481 | AC35: =3+W35 -> 4 | AD35: =O96 -> 0.15618701 | AE35: =4+W35 -> 5 | AF35: =Q96 -> 0.54603344 | AG35: =5+W35 -> 6 | AH35: =S96 -> 1.1544474
W36: =W35 -> 1 | X36: =I97 -> 1.0978688 | Y36: =W36+1 -> 2 | Z36: =K97 -> 0.14579369 | AA36: =2+W36 -> 3 | AB36: =M97 -> 0.19652303 | AC36: =3+W36 -> 4 | AD36: =O97 -> 0.22540249 | AE36: =4+W36 -> 5 | AF36: =Q97 -> 0.21574294 | AG36: =5+W36 -> 6 | AH36: =S97 -> 1.1888813
W37: =W36 -> 1 | X37: =I98 -> 0.9496455 | Y37: =W37+1 -> 2 | Z37: =K98 -> 0.18241802 | AA37: =2+W37 -> 3 | AB37: =M98 -> 0.22371693 | AC37: =3+W37 -> 4 | AD37: =O98 -> 0.157716 | AE37: =4+W37 -> 5 | AF37: =Q98 -> 0.2445471 | AG37: =5+W37 -> 6 | AH37: =S98 -> 1.1379668
U38: Gene 4 | V38: =C134 -> MDA5 | W38: 1.157 | X38: =I136 -> 0.95731126 | Y38: =W38+1 -> 2.157 | Z38: =K136 -> 0.13073718 | AA38: =2+W38 -> 3.157 | AB38: =M136 -> 0.2773961 | AC38: =3+W38 -> 4.157 | AD38: =O136 -> 0.050831044 | AE38: =4+W38 -> 5.157 | AF38: =Q136 -> 0.10646656 | AG38: =5+W38 -> 6.157 | AH38: =S136 -> 2.0542703
W39: =W38 -> 1.157 | X39: =I137 -> 1.2481682 | Y39: =W39+1 -> 2.157 | Z39: =K137 -> 0.12537895 | AA39: =2+W39 -> 3.157 | AB39: =M137 -> 0.33283429 | AC39: =3+W39 -> 4.157 | AD39: =O137 -> 0.027780139 | AE39: =4+W39 -> 5.157 | AF39: =Q137 -> 0.02690189 | AG39: =5+W39 -> 6.157 | AH39: =S137 -> 2.0530444
W40: =W38 -> 1.157 | X40: =I138 -> 0.83690029 | Y40: =W40+1 -> 2.157 | Z40: =K138 -> 0.059698233 | AA40: =2+W40 -> 3.157 | AB40: =M138 -> 0.25252212 | AC40: =3+W40 -> 4.157 | AD40: =O138 -> 0.032949011 | AE40: =4+W40 -> 5.157 | AF40: =Q138 -> 0.026780611 | AG40: =5+W40 -> 6.157 | AH40: =S138 -> 2.1999259
U41: Gene 5 | V41: =C174 -> IFIT | W41: 1.305 | X41: =I176 -> 0.87671095 | Y41: =W41+1 -> 2.305 | Z41: =K176 -> 0.22329541 | AA41: =2+W41 -> 3.305 | AB41: =M176 -> 0.50860097 | AC41: =3+W41 -> 4.305 | AD41: =O176 -> 0.43754655 | AE41: =4+W41 -> 5.305 | AF41: =Q176 -> 0.43458713 | AG41: =5+W41 -> 6.305 | AH41: =S176 -> 2.0745044
W42: =W41 -> 1.305 | X42: =I177 -> 1.1804251 | Y42: =W42+1 -> 2.305 | Z42: =K177 -> 0.33749799 | AA42: =2+W42 -> 3.305 | AB42: =M177 -> 0.74603541 | AC42: =3+W42 -> 4.305 | AD42: =O177 -> 0.27684799 | AE42: =4+W42 -> 5.305 | AF42: =Q177 -> 0.2009293 | AG42: =5+W42 -> 6.305 | AH42: =S177 -> 2.115902
W43: =W42 -> 1.305 | X43: =I178 -> 0.96628477 | Y43: =W43+1 -> 2.305 | Z43: =K178 -> 0.17976462 | AA43: =2+W43 -> 3.305 | AB43: =M178 -> 0.56076161 | AC43: =3+W43 -> 4.305 | AD43: =O178 -> 0.21684233 | AE43: =4+W43 -> 5.305 | AF43: =Q178 -> 0.26763347 | AG43: =5+W43 -> 6.305 | AH43: =S178 -> 1.8726528
C53: Gene 2
C54: =Calculations_1!B63 -> GFP
C55: Sample | D55: 2-∆∆Cq | E55: Avg. 2-∆∆Cq | F55: Std. Dev 2-∆∆Cq | H55: =(B56) & "x" -> WT 24hx | I55: =B56 -> WT 24h | J55: =B59 & "x" -> Set 1 24hx | K55: =B59 -> Set 1 24h | L55: =B62 & "x" -> Set 2 24hx | M55: =B62 -> Set 2 24h | N55: =B65 & "x" -> Set 4 24hx | O55: =B65 -> Set 4 24h | P55: =B68 & "x" -> Set 5 24hx | Q55: =B68 -> Set 5 24h | R55: =B71 & "x" -> GFP 24hx | S55: =B71 -> GFP 24h
B56: =Calculations_1!E3 -> WT 24h | C56: =Calculations_1!D63 -> WT 24h | D56: =Calculations_1!K63 -> 1.056759 | E56: =AVERAGE(D56:D58) -> 1.003724 | F56: =STDEV(D56:D58) -> 0.10369401 | H56: 1.002 | I56: =D56 -> 1.056759 | J56: 2.002 | K56: =D59 -> 0.69367656 | L56: 3.002 | M56: =D62 -> 0.30950713 | N56: 4.002 | O56: =D65 -> 0.83292123 | P56: 5.002 | Q56: =D68 -> 1.8018019 | R56: 6.002 | S56: =D71 -> 0.10088557
C57: =Calculations_1!D66 -> WT 24h | D57: =Calculations_1!K66 -> 1.0701737 | H57: 1.002 | I57: =D57 -> 1.0701737 | J57: 2.002 | K57: =D60 -> 0.27279708 | L57: 3.002 | M57: =D63 -> 0.32293026 | N57: 4.002 | O57: =D66 -> 0.86582335 | P57: 5.002 | Q57: =D69 -> 0.7164504 | R57: 6.002 | S57: =D72 -> 0.22660639
C58: =Calculations_1!D69 -> WT 24h | D58: =Calculations_1!K69 -> 0.8842392 | H58: 1.002 | I58: =D58 -> 0.8842392 | J58: 2.002 | K58: =D61 -> 0.39217031 | L58: 3.002 | M58: =D64 -> 0.30863041 | N58: 4.002 | O58: =D67 -> 0.76086563 | P58: 5.002 | Q58: =D70 -> 0.571612 | R58: 6.002 | S58: =D73 -> 0.17303247
B59: =Calculations_1!Q3 -> Set 1 24h | C59: =Calculations_1!P63 -> Set 1 24h | D59: =Calculations_1!V63 -> 0.69367656 | E59: =AVERAGE(D59:D61) -> 0.45288132 | F59: =STDEV(D59:D61) -> 0.2169084
C60: =Calculations_1!P66 -> Set 1 24h | D60: =Calculations_1!V66 -> 0.27279708 | I60: =B56 -> WT 24h | J60: =B59 -> Set 1 24h | K60: =B62 -> Set 2 24h | L60: =B65 -> Set 4 24h | M60: =B68 -> Set 5 24h | N60: =B71 -> GFP 24h
...
